[2024-10-14T04:55:20.010+0000] {local_task_job_runner.py:123} INFO - ::group::Pre task execution logs
[2024-10-14T04:55:20.027+0000] {taskinstance.py:2612} INFO - Dependencies all met for dep_context=non-requeueable deps ti=<TaskInstance: kaggle_ml_pipeline.EvaluateModel manual__2024-10-14T04:54:58.226225+00:00 [queued]>
[2024-10-14T04:55:20.035+0000] {taskinstance.py:2612} INFO - Dependencies all met for dep_context=requeueable deps ti=<TaskInstance: kaggle_ml_pipeline.EvaluateModel manual__2024-10-14T04:54:58.226225+00:00 [queued]>
[2024-10-14T04:55:20.036+0000] {taskinstance.py:2865} INFO - Starting attempt 1 of 2
[2024-10-14T04:55:20.047+0000] {taskinstance.py:2888} INFO - Executing <Task(PythonOperator): EvaluateModel> on 2024-10-14 04:54:58.226225+00:00
[2024-10-14T04:55:20.058+0000] {warnings.py:112} WARNING - /home/***/.local/lib/python3.12/site-packages/***/task/task_runner/standard_task_runner.py:70: DeprecationWarning: This process (pid=6495) is multi-threaded, use of fork() may lead to deadlocks in the child.
  pid = os.fork()

[2024-10-14T04:55:20.059+0000] {standard_task_runner.py:72} INFO - Started process 6538 to run task
[2024-10-14T04:55:20.059+0000] {standard_task_runner.py:104} INFO - Running: ['***', 'tasks', 'run', 'kaggle_ml_pipeline', 'EvaluateModel', 'manual__2024-10-14T04:54:58.226225+00:00', '--job-id', '104', '--raw', '--subdir', 'DAGS_FOLDER/dmc_pipeline.py', '--cfg-path', '/tmp/tmpqw2xim7v']
[2024-10-14T04:55:20.060+0000] {standard_task_runner.py:105} INFO - Job 104: Subtask EvaluateModel
[2024-10-14T04:55:20.098+0000] {task_command.py:467} INFO - Running <TaskInstance: kaggle_ml_pipeline.EvaluateModel manual__2024-10-14T04:54:58.226225+00:00 [running]> on host 3865df127200
[2024-10-14T04:55:20.175+0000] {taskinstance.py:3131} INFO - Exporting env vars: AIRFLOW_CTX_DAG_OWNER='***' AIRFLOW_CTX_DAG_ID='kaggle_ml_pipeline' AIRFLOW_CTX_TASK_ID='EvaluateModel' AIRFLOW_CTX_EXECUTION_DATE='2024-10-14T04:54:58.226225+00:00' AIRFLOW_CTX_TRY_NUMBER='1' AIRFLOW_CTX_DAG_RUN_ID='manual__2024-10-14T04:54:58.226225+00:00'
[2024-10-14T04:55:20.176+0000] {logging_mixin.py:190} INFO - Task instance is in running state
[2024-10-14T04:55:20.176+0000] {logging_mixin.py:190} INFO -  Previous state of the Task instance: queued
[2024-10-14T04:55:20.177+0000] {logging_mixin.py:190} INFO - Current task name:EvaluateModel state:running start_date:2024-10-14 04:55:20.027942+00:00
[2024-10-14T04:55:20.177+0000] {logging_mixin.py:190} INFO - Dag name:kaggle_ml_pipeline and current dag run status:running
[2024-10-14T04:55:20.178+0000] {taskinstance.py:731} INFO - ::endgroup::
[2024-10-14T04:55:20.282+0000] {logging_mixin.py:190} INFO - Modelo cargado desde opt/***/dags/data/model_dmc.joblib
[2024-10-14T04:55:20.338+0000] {taskinstance.py:3310} ERROR - Task failed with exception
Traceback (most recent call last):
  File "/home/airflow/.local/lib/python3.12/site-packages/airflow/models/taskinstance.py", line 767, in _execute_task
    result = _execute_callable(context=context, **execute_callable_kwargs)
             ^^^^^^^^^^^^^^^^^^^^^^^^^^^^^^^^^^^^^^^^^^^^^^^^^^^^^^^^^^^^^
  File "/home/airflow/.local/lib/python3.12/site-packages/airflow/models/taskinstance.py", line 733, in _execute_callable
    return ExecutionCallableRunner(
           ^^^^^^^^^^^^^^^^^^^^^^^^
  File "/home/airflow/.local/lib/python3.12/site-packages/airflow/utils/operator_helpers.py", line 252, in run
    return self.func(*args, **kwargs)
           ^^^^^^^^^^^^^^^^^^^^^^^^^^
  File "/home/airflow/.local/lib/python3.12/site-packages/airflow/models/baseoperator.py", line 406, in wrapper
    return func(self, *args, **kwargs)
           ^^^^^^^^^^^^^^^^^^^^^^^^^^^
  File "/home/airflow/.local/lib/python3.12/site-packages/airflow/operators/python.py", line 238, in execute
    return_value = self.execute_callable()
                   ^^^^^^^^^^^^^^^^^^^^^^^
  File "/home/airflow/.local/lib/python3.12/site-packages/airflow/operators/python.py", line 256, in execute_callable
    return runner.run(*self.op_args, **self.op_kwargs)
           ^^^^^^^^^^^^^^^^^^^^^^^^^^^^^^^^^^^^^^^^^^^
  File "/home/airflow/.local/lib/python3.12/site-packages/airflow/utils/operator_helpers.py", line 252, in run
    return self.func(*args, **kwargs)
           ^^^^^^^^^^^^^^^^^^^^^^^^^^
  File "/opt/airflow/dags/dmc_pipeline.py", line 98, in evaluate_model
    X_test = df_test.drop('target', axis=1)
             ^^^^^^^^^^^^^^^^^^^^^^^^^^^^^^
  File "/home/airflow/.local/lib/python3.12/site-packages/pandas/core/frame.py", line 5344, in drop
    return super().drop(
           ^^^^^^^^^^^^^
  File "/home/airflow/.local/lib/python3.12/site-packages/pandas/core/generic.py", line 4711, in drop
    obj = obj._drop_axis(labels, axis, level=level, errors=errors)
          ^^^^^^^^^^^^^^^^^^^^^^^^^^^^^^^^^^^^^^^^^^^^^^^^^^^^^^^^
  File "/home/airflow/.local/lib/python3.12/site-packages/pandas/core/generic.py", line 4753, in _drop_axis
    new_axis = axis.drop(labels, errors=errors)
               ^^^^^^^^^^^^^^^^^^^^^^^^^^^^^^^^
  File "/home/airflow/.local/lib/python3.12/site-packages/pandas/core/indexes/base.py", line 7000, in drop
    raise KeyError(f"{labels[mask].tolist()} not found in axis")
KeyError: "['target'] not found in axis"
[2024-10-14T04:55:20.356+0000] {logging_mixin.py:190} INFO - Task instance in failure state
[2024-10-14T04:55:20.356+0000] {logging_mixin.py:190} INFO - Task start:2024-10-14 04:55:20.027942+00:00 end:2024-10-14 04:55:20.355619+00:00 duration:0.327677
[2024-10-14T04:55:20.357+0000] {logging_mixin.py:190} INFO - Task:<Task(PythonOperator): EvaluateModel> dag:<DAG: kaggle_ml_pipeline> dagrun:<DagRun kaggle_ml_pipeline @ 2024-10-14 04:54:58.226225+00:00: manual__2024-10-14T04:54:58.226225+00:00, state:running, queued_at: 2024-10-14 04:54:58.235963+00:00. externally triggered: True>
[2024-10-14T04:55:20.357+0000] {logging_mixin.py:190} INFO - Failure caused by "['target'] not found in axis"
[2024-10-14T04:55:20.357+0000] {taskinstance.py:1225} INFO - Marking task as UP_FOR_RETRY. dag_id=kaggle_ml_pipeline, task_id=EvaluateModel, run_id=manual__2024-10-14T04:54:58.226225+00:00, execution_date=20241014T045458, start_date=20241014T045520, end_date=20241014T045520
[2024-10-14T04:55:20.374+0000] {taskinstance.py:340} INFO - ::group::Post task execution logs
[2024-10-14T04:55:20.375+0000] {standard_task_runner.py:124} ERROR - Failed to execute job 104 for task EvaluateModel ("['target'] not found in axis"; 6538)
Traceback (most recent call last):
  File "/home/airflow/.local/lib/python3.12/site-packages/airflow/task/task_runner/standard_task_runner.py", line 117, in _start_by_fork
    ret = args.func(args, dag=self.dag)
          ^^^^^^^^^^^^^^^^^^^^^^^^^^^^^
  File "/home/airflow/.local/lib/python3.12/site-packages/airflow/cli/cli_config.py", line 49, in command
    return func(*args, **kwargs)
           ^^^^^^^^^^^^^^^^^^^^^
  File "/home/airflow/.local/lib/python3.12/site-packages/airflow/utils/cli.py", line 115, in wrapper
    return f(*args, **kwargs)
           ^^^^^^^^^^^^^^^^^^
  File "/home/airflow/.local/lib/python3.12/site-packages/airflow/cli/commands/task_command.py", line 483, in task_run
    task_return_code = _run_task_by_selected_method(args, _dag, ti)
                       ^^^^^^^^^^^^^^^^^^^^^^^^^^^^^^^^^^^^^^^^^^^^
  File "/home/airflow/.local/lib/python3.12/site-packages/airflow/cli/commands/task_command.py", line 256, in _run_task_by_selected_method
    return _run_raw_task(args, ti)
           ^^^^^^^^^^^^^^^^^^^^^^^
  File "/home/airflow/.local/lib/python3.12/site-packages/airflow/cli/commands/task_command.py", line 341, in _run_raw_task
    return ti._run_raw_task(
           ^^^^^^^^^^^^^^^^^
  File "/home/airflow/.local/lib/python3.12/site-packages/airflow/utils/session.py", line 97, in wrapper
    return func(*args, session=session, **kwargs)
           ^^^^^^^^^^^^^^^^^^^^^^^^^^^^^^^^^^^^^^
  File "/home/airflow/.local/lib/python3.12/site-packages/airflow/models/taskinstance.py", line 3004, in _run_raw_task
    return _run_raw_task(
           ^^^^^^^^^^^^^^
  File "/home/airflow/.local/lib/python3.12/site-packages/airflow/models/taskinstance.py", line 273, in _run_raw_task
    TaskInstance._execute_task_with_callbacks(
  File "/home/airflow/.local/lib/python3.12/site-packages/airflow/models/taskinstance.py", line 3158, in _execute_task_with_callbacks
    result = self._execute_task(context, task_orig)
             ^^^^^^^^^^^^^^^^^^^^^^^^^^^^^^^^^^^^^^
  File "/home/airflow/.local/lib/python3.12/site-packages/airflow/models/taskinstance.py", line 3182, in _execute_task
    return _execute_task(self, context, task_orig)
           ^^^^^^^^^^^^^^^^^^^^^^^^^^^^^^^^^^^^^^^
  File "/home/airflow/.local/lib/python3.12/site-packages/airflow/models/taskinstance.py", line 767, in _execute_task
    result = _execute_callable(context=context, **execute_callable_kwargs)
             ^^^^^^^^^^^^^^^^^^^^^^^^^^^^^^^^^^^^^^^^^^^^^^^^^^^^^^^^^^^^^
  File "/home/airflow/.local/lib/python3.12/site-packages/airflow/models/taskinstance.py", line 733, in _execute_callable
    return ExecutionCallableRunner(
           ^^^^^^^^^^^^^^^^^^^^^^^^
  File "/home/airflow/.local/lib/python3.12/site-packages/airflow/utils/operator_helpers.py", line 252, in run
    return self.func(*args, **kwargs)
           ^^^^^^^^^^^^^^^^^^^^^^^^^^
  File "/home/airflow/.local/lib/python3.12/site-packages/airflow/models/baseoperator.py", line 406, in wrapper
    return func(self, *args, **kwargs)
           ^^^^^^^^^^^^^^^^^^^^^^^^^^^
  File "/home/airflow/.local/lib/python3.12/site-packages/airflow/operators/python.py", line 238, in execute
    return_value = self.execute_callable()
                   ^^^^^^^^^^^^^^^^^^^^^^^
  File "/home/airflow/.local/lib/python3.12/site-packages/airflow/operators/python.py", line 256, in execute_callable
    return runner.run(*self.op_args, **self.op_kwargs)
           ^^^^^^^^^^^^^^^^^^^^^^^^^^^^^^^^^^^^^^^^^^^
  File "/home/airflow/.local/lib/python3.12/site-packages/airflow/utils/operator_helpers.py", line 252, in run
    return self.func(*args, **kwargs)
           ^^^^^^^^^^^^^^^^^^^^^^^^^^
  File "/opt/airflow/dags/dmc_pipeline.py", line 98, in evaluate_model
    X_test = df_test.drop('target', axis=1)
             ^^^^^^^^^^^^^^^^^^^^^^^^^^^^^^
  File "/home/airflow/.local/lib/python3.12/site-packages/pandas/core/frame.py", line 5344, in drop
    return super().drop(
           ^^^^^^^^^^^^^
  File "/home/airflow/.local/lib/python3.12/site-packages/pandas/core/generic.py", line 4711, in drop
    obj = obj._drop_axis(labels, axis, level=level, errors=errors)
          ^^^^^^^^^^^^^^^^^^^^^^^^^^^^^^^^^^^^^^^^^^^^^^^^^^^^^^^^
  File "/home/airflow/.local/lib/python3.12/site-packages/pandas/core/generic.py", line 4753, in _drop_axis
    new_axis = axis.drop(labels, errors=errors)
               ^^^^^^^^^^^^^^^^^^^^^^^^^^^^^^^^
  File "/home/airflow/.local/lib/python3.12/site-packages/pandas/core/indexes/base.py", line 7000, in drop
    raise KeyError(f"{labels[mask].tolist()} not found in axis")
KeyError: "['target'] not found in axis"
[2024-10-14T04:55:20.435+0000] {local_task_job_runner.py:266} INFO - Task exited with return code 1
[2024-10-14T04:55:20.449+0000] {taskinstance.py:3900} INFO - 0 downstream tasks scheduled from follow-on schedule check
[2024-10-14T04:55:20.451+0000] {local_task_job_runner.py:245} INFO - ::endgroup::
