[2024-10-14T04:47:46.503+0000] {local_task_job_runner.py:123} INFO - ::group::Pre task execution logs
[2024-10-14T04:47:46.516+0000] {taskinstance.py:2612} INFO - Dependencies all met for dep_context=non-requeueable deps ti=<TaskInstance: kaggle_ml_pipeline.GetDataKaggle manual__2024-10-14T04:47:44.141159+00:00 [queued]>
[2024-10-14T04:47:46.522+0000] {taskinstance.py:2612} INFO - Dependencies all met for dep_context=requeueable deps ti=<TaskInstance: kaggle_ml_pipeline.GetDataKaggle manual__2024-10-14T04:47:44.141159+00:00 [queued]>
[2024-10-14T04:47:46.523+0000] {taskinstance.py:2865} INFO - Starting attempt 1 of 2
[2024-10-14T04:47:46.534+0000] {taskinstance.py:2888} INFO - Executing <Task(PythonOperator): GetDataKaggle> on 2024-10-14 04:47:44.141159+00:00
[2024-10-14T04:47:46.543+0000] {warnings.py:112} WARNING - /home/***/.local/lib/python3.12/site-packages/***/task/task_runner/standard_task_runner.py:70: DeprecationWarning: This process (pid=5696) is multi-threaded, use of fork() may lead to deadlocks in the child.
  pid = os.fork()

[2024-10-14T04:47:46.545+0000] {standard_task_runner.py:72} INFO - Started process 5739 to run task
[2024-10-14T04:47:46.544+0000] {standard_task_runner.py:104} INFO - Running: ['***', 'tasks', 'run', 'kaggle_ml_pipeline', 'GetDataKaggle', 'manual__2024-10-14T04:47:44.141159+00:00', '--job-id', '91', '--raw', '--subdir', 'DAGS_FOLDER/dmc_pipeline.py', '--cfg-path', '/tmp/tmpkntbh7e4']
[2024-10-14T04:47:46.545+0000] {standard_task_runner.py:105} INFO - Job 91: Subtask GetDataKaggle
[2024-10-14T04:47:46.581+0000] {task_command.py:467} INFO - Running <TaskInstance: kaggle_ml_pipeline.GetDataKaggle manual__2024-10-14T04:47:44.141159+00:00 [running]> on host 3865df127200
[2024-10-14T04:47:46.646+0000] {taskinstance.py:3131} INFO - Exporting env vars: AIRFLOW_CTX_DAG_OWNER='***' AIRFLOW_CTX_DAG_ID='kaggle_ml_pipeline' AIRFLOW_CTX_TASK_ID='GetDataKaggle' AIRFLOW_CTX_EXECUTION_DATE='2024-10-14T04:47:44.141159+00:00' AIRFLOW_CTX_TRY_NUMBER='1' AIRFLOW_CTX_DAG_RUN_ID='manual__2024-10-14T04:47:44.141159+00:00'
[2024-10-14T04:47:46.648+0000] {logging_mixin.py:190} INFO - Task instance is in running state
[2024-10-14T04:47:46.648+0000] {logging_mixin.py:190} INFO -  Previous state of the Task instance: queued
[2024-10-14T04:47:46.648+0000] {logging_mixin.py:190} INFO - Current task name:GetDataKaggle state:running start_date:2024-10-14 04:47:46.517277+00:00
[2024-10-14T04:47:46.649+0000] {logging_mixin.py:190} INFO - Dag name:kaggle_ml_pipeline and current dag run status:running
[2024-10-14T04:47:46.649+0000] {taskinstance.py:731} INFO - ::endgroup::
[2024-10-14T04:47:46.659+0000] {taskinstance.py:3310} ERROR - Task failed with exception
Traceback (most recent call last):
  File "/home/airflow/.local/lib/python3.12/site-packages/airflow/models/taskinstance.py", line 767, in _execute_task
    result = _execute_callable(context=context, **execute_callable_kwargs)
             ^^^^^^^^^^^^^^^^^^^^^^^^^^^^^^^^^^^^^^^^^^^^^^^^^^^^^^^^^^^^^
  File "/home/airflow/.local/lib/python3.12/site-packages/airflow/models/taskinstance.py", line 733, in _execute_callable
    return ExecutionCallableRunner(
           ^^^^^^^^^^^^^^^^^^^^^^^^
  File "/home/airflow/.local/lib/python3.12/site-packages/airflow/utils/operator_helpers.py", line 252, in run
    return self.func(*args, **kwargs)
           ^^^^^^^^^^^^^^^^^^^^^^^^^^
  File "/home/airflow/.local/lib/python3.12/site-packages/airflow/models/baseoperator.py", line 406, in wrapper
    return func(self, *args, **kwargs)
           ^^^^^^^^^^^^^^^^^^^^^^^^^^^
  File "/home/airflow/.local/lib/python3.12/site-packages/airflow/operators/python.py", line 238, in execute
    return_value = self.execute_callable()
                   ^^^^^^^^^^^^^^^^^^^^^^^
  File "/home/airflow/.local/lib/python3.12/site-packages/airflow/operators/python.py", line 256, in execute_callable
    return runner.run(*self.op_args, **self.op_kwargs)
           ^^^^^^^^^^^^^^^^^^^^^^^^^^^^^^^^^^^^^^^^^^^
  File "/home/airflow/.local/lib/python3.12/site-packages/airflow/utils/operator_helpers.py", line 252, in run
    return self.func(*args, **kwargs)
           ^^^^^^^^^^^^^^^^^^^^^^^^^^
  File "/opt/airflow/dags/dmc_pipeline.py", line 52, in GetDataKaggle
    os.makedirs(data_path, exist_ok=True)
                ^^^^^^^^^
NameError: name 'data_path' is not defined
[2024-10-14T04:47:46.676+0000] {logging_mixin.py:190} INFO - Task instance in failure state
[2024-10-14T04:47:46.677+0000] {logging_mixin.py:190} INFO - Task start:2024-10-14 04:47:46.517277+00:00 end:2024-10-14 04:47:46.676354+00:00 duration:0.159077
[2024-10-14T04:47:46.677+0000] {logging_mixin.py:190} INFO - Task:<Task(PythonOperator): GetDataKaggle> dag:<DAG: kaggle_ml_pipeline> dagrun:<DagRun kaggle_ml_pipeline @ 2024-10-14 04:47:44.141159+00:00: manual__2024-10-14T04:47:44.141159+00:00, state:running, queued_at: 2024-10-14 04:47:44.150658+00:00. externally triggered: True>
[2024-10-14T04:47:46.678+0000] {logging_mixin.py:190} INFO - Failure caused by name 'data_path' is not defined
[2024-10-14T04:47:46.678+0000] {taskinstance.py:1225} INFO - Marking task as UP_FOR_RETRY. dag_id=kaggle_ml_pipeline, task_id=GetDataKaggle, run_id=manual__2024-10-14T04:47:44.141159+00:00, execution_date=20241014T044744, start_date=20241014T044746, end_date=20241014T044746
[2024-10-14T04:47:46.690+0000] {taskinstance.py:340} INFO - ::group::Post task execution logs
[2024-10-14T04:47:46.691+0000] {standard_task_runner.py:124} ERROR - Failed to execute job 91 for task GetDataKaggle (name 'data_path' is not defined; 5739)
Traceback (most recent call last):
  File "/home/airflow/.local/lib/python3.12/site-packages/airflow/task/task_runner/standard_task_runner.py", line 117, in _start_by_fork
    ret = args.func(args, dag=self.dag)
          ^^^^^^^^^^^^^^^^^^^^^^^^^^^^^
  File "/home/airflow/.local/lib/python3.12/site-packages/airflow/cli/cli_config.py", line 49, in command
    return func(*args, **kwargs)
           ^^^^^^^^^^^^^^^^^^^^^
  File "/home/airflow/.local/lib/python3.12/site-packages/airflow/utils/cli.py", line 115, in wrapper
    return f(*args, **kwargs)
           ^^^^^^^^^^^^^^^^^^
  File "/home/airflow/.local/lib/python3.12/site-packages/airflow/cli/commands/task_command.py", line 483, in task_run
    task_return_code = _run_task_by_selected_method(args, _dag, ti)
                       ^^^^^^^^^^^^^^^^^^^^^^^^^^^^^^^^^^^^^^^^^^^^
  File "/home/airflow/.local/lib/python3.12/site-packages/airflow/cli/commands/task_command.py", line 256, in _run_task_by_selected_method
    return _run_raw_task(args, ti)
           ^^^^^^^^^^^^^^^^^^^^^^^
  File "/home/airflow/.local/lib/python3.12/site-packages/airflow/cli/commands/task_command.py", line 341, in _run_raw_task
    return ti._run_raw_task(
           ^^^^^^^^^^^^^^^^^
  File "/home/airflow/.local/lib/python3.12/site-packages/airflow/utils/session.py", line 97, in wrapper
    return func(*args, session=session, **kwargs)
           ^^^^^^^^^^^^^^^^^^^^^^^^^^^^^^^^^^^^^^
  File "/home/airflow/.local/lib/python3.12/site-packages/airflow/models/taskinstance.py", line 3004, in _run_raw_task
    return _run_raw_task(
           ^^^^^^^^^^^^^^
  File "/home/airflow/.local/lib/python3.12/site-packages/airflow/models/taskinstance.py", line 273, in _run_raw_task
    TaskInstance._execute_task_with_callbacks(
  File "/home/airflow/.local/lib/python3.12/site-packages/airflow/models/taskinstance.py", line 3158, in _execute_task_with_callbacks
    result = self._execute_task(context, task_orig)
             ^^^^^^^^^^^^^^^^^^^^^^^^^^^^^^^^^^^^^^
  File "/home/airflow/.local/lib/python3.12/site-packages/airflow/models/taskinstance.py", line 3182, in _execute_task
    return _execute_task(self, context, task_orig)
           ^^^^^^^^^^^^^^^^^^^^^^^^^^^^^^^^^^^^^^^
  File "/home/airflow/.local/lib/python3.12/site-packages/airflow/models/taskinstance.py", line 767, in _execute_task
    result = _execute_callable(context=context, **execute_callable_kwargs)
             ^^^^^^^^^^^^^^^^^^^^^^^^^^^^^^^^^^^^^^^^^^^^^^^^^^^^^^^^^^^^^
  File "/home/airflow/.local/lib/python3.12/site-packages/airflow/models/taskinstance.py", line 733, in _execute_callable
    return ExecutionCallableRunner(
           ^^^^^^^^^^^^^^^^^^^^^^^^
  File "/home/airflow/.local/lib/python3.12/site-packages/airflow/utils/operator_helpers.py", line 252, in run
    return self.func(*args, **kwargs)
           ^^^^^^^^^^^^^^^^^^^^^^^^^^
  File "/home/airflow/.local/lib/python3.12/site-packages/airflow/models/baseoperator.py", line 406, in wrapper
    return func(self, *args, **kwargs)
           ^^^^^^^^^^^^^^^^^^^^^^^^^^^
  File "/home/airflow/.local/lib/python3.12/site-packages/airflow/operators/python.py", line 238, in execute
    return_value = self.execute_callable()
                   ^^^^^^^^^^^^^^^^^^^^^^^
  File "/home/airflow/.local/lib/python3.12/site-packages/airflow/operators/python.py", line 256, in execute_callable
    return runner.run(*self.op_args, **self.op_kwargs)
           ^^^^^^^^^^^^^^^^^^^^^^^^^^^^^^^^^^^^^^^^^^^
  File "/home/airflow/.local/lib/python3.12/site-packages/airflow/utils/operator_helpers.py", line 252, in run
    return self.func(*args, **kwargs)
           ^^^^^^^^^^^^^^^^^^^^^^^^^^
  File "/opt/airflow/dags/dmc_pipeline.py", line 52, in GetDataKaggle
    os.makedirs(data_path, exist_ok=True)
                ^^^^^^^^^
NameError: name 'data_path' is not defined
[2024-10-14T04:47:46.719+0000] {local_task_job_runner.py:266} INFO - Task exited with return code 1
[2024-10-14T04:47:46.737+0000] {taskinstance.py:3900} INFO - 0 downstream tasks scheduled from follow-on schedule check
[2024-10-14T04:47:46.739+0000] {local_task_job_runner.py:245} INFO - ::endgroup::
